[2024-05-10T09:47:57.881+0000] {local_task_job_runner.py:120} INFO - ::group::Pre task execution logs
[2024-05-10T09:47:57.901+0000] {taskinstance.py:2073} INFO - Dependencies all met for dep_context=non-requeueable deps ti=<TaskInstance: file_process_dag.process_file manual__2024-05-10T09:47:55.520977+00:00 [queued]>
[2024-05-10T09:47:57.908+0000] {taskinstance.py:2073} INFO - Dependencies all met for dep_context=requeueable deps ti=<TaskInstance: file_process_dag.process_file manual__2024-05-10T09:47:55.520977+00:00 [queued]>
[2024-05-10T09:47:57.908+0000] {taskinstance.py:2303} INFO - Starting attempt 1 of 1
[2024-05-10T09:47:57.931+0000] {taskinstance.py:2327} INFO - Executing <Task(PythonOperator): process_file> on 2024-05-10 09:47:55.520977+00:00
[2024-05-10T09:47:57.936+0000] {warnings.py:110} WARNING - /home/***/.local/lib/python3.12/site-packages/***/task/task_runner/standard_task_runner.py:61: DeprecationWarning: This process (pid=1237) is multi-threaded, use of fork() may lead to deadlocks in the child.
  pid = os.fork()

[2024-05-10T09:47:57.937+0000] {standard_task_runner.py:63} INFO - Started process 1245 to run task
[2024-05-10T09:47:57.937+0000] {standard_task_runner.py:90} INFO - Running: ['***', 'tasks', 'run', 'file_process_dag', 'process_file', 'manual__2024-05-10T09:47:55.520977+00:00', '--job-id', '38', '--raw', '--subdir', 'DAGS_FOLDER/basic_processing.py', '--cfg-path', '/tmp/tmpe27zd0yt']
[2024-05-10T09:47:57.939+0000] {standard_task_runner.py:91} INFO - Job 38: Subtask process_file
[2024-05-10T09:47:57.986+0000] {task_command.py:426} INFO - Running <TaskInstance: file_process_dag.process_file manual__2024-05-10T09:47:55.520977+00:00 [running]> on host 24b77fb676b2
[2024-05-10T09:47:58.142+0000] {taskinstance.py:2644} INFO - Exporting env vars: AIRFLOW_CTX_DAG_OWNER='***' AIRFLOW_CTX_DAG_ID='file_process_dag' AIRFLOW_CTX_TASK_ID='process_file' AIRFLOW_CTX_EXECUTION_DATE='2024-05-10T09:47:55.520977+00:00' AIRFLOW_CTX_TRY_NUMBER='1' AIRFLOW_CTX_DAG_RUN_ID='manual__2024-05-10T09:47:55.520977+00:00'
[2024-05-10T09:47:58.143+0000] {taskinstance.py:430} INFO - ::endgroup::
[2024-05-10T09:47:58.155+0000] {logging_mixin.py:188} INFO - Force unix newline characters
[2024-05-10T09:47:58.155+0000] {logging_mixin.py:188} INFO - dos2unix /opt/***/storage/dest/*
[2024-05-10T09:47:58.156+0000] {taskinstance.py:441} INFO - ::group::Post task execution logs
[2024-05-10T09:47:58.156+0000] {taskinstance.py:2890} ERROR - Task failed with exception
Traceback (most recent call last):
  File "/home/airflow/.local/lib/python3.12/site-packages/airflow/models/taskinstance.py", line 465, in _execute_task
    result = _execute_callable(context=context, **execute_callable_kwargs)
             ^^^^^^^^^^^^^^^^^^^^^^^^^^^^^^^^^^^^^^^^^^^^^^^^^^^^^^^^^^^^^
  File "/home/airflow/.local/lib/python3.12/site-packages/airflow/models/taskinstance.py", line 432, in _execute_callable
    return execute_callable(context=context, **execute_callable_kwargs)
           ^^^^^^^^^^^^^^^^^^^^^^^^^^^^^^^^^^^^^^^^^^^^^^^^^^^^^^^^^^^^
  File "/home/airflow/.local/lib/python3.12/site-packages/airflow/models/baseoperator.py", line 400, in wrapper
    return func(self, *args, **kwargs)
           ^^^^^^^^^^^^^^^^^^^^^^^^^^^
  File "/home/airflow/.local/lib/python3.12/site-packages/airflow/operators/python.py", line 235, in execute
    return_value = self.execute_callable()
                   ^^^^^^^^^^^^^^^^^^^^^^^
  File "/home/airflow/.local/lib/python3.12/site-packages/airflow/operators/python.py", line 252, in execute_callable
    return self.python_callable(*self.op_args, **self.op_kwargs)
           ^^^^^^^^^^^^^^^^^^^^^^^^^^^^^^^^^^^^^^^^^^^^^^^^^^^^^
  File "/opt/airflow/dags/scripts/text_processing/basic_processing.py", line 37, in force_unix_newlines
    subprocess.run(["dos2unix", all_files])
  File "/usr/local/lib/python3.12/subprocess.py", line 548, in run
    with Popen(*popenargs, **kwargs) as process:
         ^^^^^^^^^^^^^^^^^^^^^^^^^^^
  File "/usr/local/lib/python3.12/subprocess.py", line 1026, in __init__
    self._execute_child(args, executable, preexec_fn, close_fds,
  File "/usr/local/lib/python3.12/subprocess.py", line 1953, in _execute_child
    raise child_exception_type(errno_num, err_msg, err_filename)
PermissionError: [Errno 13] Permission denied: 'dos2unix'
[2024-05-10T09:47:58.164+0000] {taskinstance.py:1205} INFO - Marking task as FAILED. dag_id=file_process_dag, task_id=process_file, execution_date=20240510T094755, start_date=20240510T094757, end_date=20240510T094758
[2024-05-10T09:47:58.186+0000] {standard_task_runner.py:110} ERROR - Failed to execute job 38 for task process_file ([Errno 13] Permission denied: 'dos2unix'; 1245)
[2024-05-10T09:47:58.199+0000] {local_task_job_runner.py:240} INFO - Task exited with return code 1
[2024-05-10T09:47:58.213+0000] {taskinstance.py:3482} INFO - 0 downstream tasks scheduled from follow-on schedule check
[2024-05-10T09:47:58.219+0000] {local_task_job_runner.py:222} INFO - ::endgroup::
